test_0 (__main__.lab3a)
[Lab 3] - [Investigation 1] - [Part 4] - Functions - Test for file creation: ./lab3a.py ... ok
test_1 (__main__.lab3a)
[Lab 3] - [Investigation 1] - [Part 4] - Functions - Test for errors running: ./lab3a.py ... ok
test_2 (__main__.lab3a)
[Lab 3] - [Investigation 1] - [Part 4] - Functions - Test for correct shebang line: ./lab3a.py ... ok
test_4_function_return_text_value (__main__.lab3a)
[Lab 3] - [Investigation 1] - [Part 4] - Functions - function print_out_text() has correct output ... ok
test_5_function_return_number_value (__main__.lab3a)
[Lab 3] - [Investigation 1] - [Part 4] - Functions - function print_out_text() has correct output ... ok
test_0 (__main__.lab3b)
[Lab 3] - [Investigation 2] - [Part 1] - Functions - Test for file creation: ./lab3b.py ... ok
test_1 (__main__.lab3b)
[Lab 3] - [Investigation 2] - [Part 1] - Functions - Test for errors running: ./lab3b.py ... ok
test_2 (__main__.lab3b)
[Lab 3] - [Investigation 2] - [Part 1] - Functions - Test for correct shebang line: ./lab3b.py ... ok
test_4_function_sum (__main__.lab3b)
[Lab 3] - [Investigation 2] - [Part 1] - functions & arguments - function sum_numbers() fails without 2 arguments ... ok
test_5_function_subtract (__main__.lab3b)
[Lab 3] - [Investigation 2] - [Part 1] - functions & arguments - function subtract_numbers() fails without 2 arguments ... ok
test_6_function_multiply (__main__.lab3b)
[Lab 3] - [Investigation 2] - [Part 1] - functions & arguments - function multiply_numbers() fails without 2 arguments ... ok
test_7_function_sum_output (__main__.lab3b)
[Lab 3] - [Investigation 2] - [Part 1] - functions & arguments - function add_numbers() adds correctly ... ok
test_8_function_subtract_output (__main__.lab3b)
[Lab 3] - [Investigation 2] - [Part 1] - functions & arguments - function subtract_numbers() subtracts correctly ... ok
test_9_function_multiply_output (__main__.lab3b)
[Lab 3] - [Investigation 2] - [Part 1] - functions & arguments - function multiply_numbers() multiplies correctly ... ok
test_0 (__main__.lab3c)
[Lab 3] - [Investigation 2] - [Part 1] - Functions - Test for file creation: ./lab3c.py ... ok
test_1 (__main__.lab3c)
[Lab 3] - [Investigation 2] - [Part 1] - Functions - Test for errors running: ./lab3c.py ... ok
test_2 (__main__.lab3c)
[Lab 3] - [Investigation 2] - [Part 1] - Functions - Test for correct shebang line: ./lab3X.py ... ok
test_4_function_sum (__main__.lab3c)
[Lab 3] - [Investigation 2] - [Part 1] - functions & arguments & logic - function operate() fails with 0 arguments ... ok
test_5_function_subtract (__main__.lab3c)
[Lab 3] - [Investigation 2] - [Part 1] - functions & arguments & logic - function operate() fails with 1 arguments ... ok
test_6_function_multiply (__main__.lab3c)
[Lab 3] - [Investigation 2] - [Part 1] - functions & arguments & logic - function operate() fails with 2 arguments ... ok
test_7_function_sum_output (__main__.lab3c)
[Lab 3] - [Investigation 2] - [Part 1] - functions & arguments & logic - function operate() adds correctly test 1 ... ok
test_8_function_subtract_output (__main__.lab3c)
[Lab 3] - [Investigation 2] - [Part 1] - functions & arguments & logic - function operate() subtracts correctly test 1 ... ok
test_9_function_multiply_output (__main__.lab3c)
[Lab 3] - [Investigation 2] - [Part 1] - functions & arguments & logic - function operate() multiplies correctly test 1 ... ok
test_a_function_sum_output (__main__.lab3c)
[Lab 3] - [Investigation 2] - [Part 1] - functions & arguments & logic - function operate() adds correctly test 2 ... ok
test_b_function_subtract_output (__main__.lab3c)
[Lab 3] - [Investigation 2] - [Part 1] - functions & arguments & logic - function operate() subtracts correctly test 2 ... ok
test_c_function_multiply_output (__main__.lab3c)
[Lab 3] - [Investigation 2] - [Part 1] - functions & arguments & logic - function operate() multiplies correctly test 2 ... ok
test_d_function_multiply_output (__main__.lab3c)
[Lab 3] - [Investigation 2] - [Part 1] - functions & arguments & logic - function operate() fails with division ... ok
test_0 (__main__.lab3d)
[Lab 3] - [Investigation 2] - [Part 2] - Functions - Test for file creation: ./lab3d.py ... ok
test_a (__main__.lab3d)
[Lab 3] - [Investigation 2] - [Part 2] - Functions - Test for errors running: ./lab3d.py ... ok
test_a1 (__main__.lab3d)
[Lab 3] - [Investigation 2] - [Part 2] - Functions - Test for correct shebang line: ./lab3d.py ... ok
test_a_function_free_space (__main__.lab3d)
[Lab 3] - [Investigation 2] - [Part 2] - functions & subprocess - Test function succeeds with 0 arguments ... /usr/lib/python3.10/subprocess.py:1070: ResourceWarning: subprocess 9756 is still running
  _warn("subprocess %s is still running" % self.pid,
ResourceWarning: Enable tracemalloc to get the object allocation traceback
/home/ops/ops445/lab3/lab3d.py:12: ResourceWarning: unclosed file <_io.TextIOWrapper name=3 encoding='UTF-8'>
  bashcommand = os.popen("df -h | grep '/$' | awk '{print $4}'").read()
ResourceWarning: Enable tracemalloc to get the object allocation traceback
FAIL

======================================================================
FAIL: test_a_function_free_space (__main__.lab3d)
[Lab 3] - [Investigation 2] - [Part 2] - functions & subprocess - Test function succeeds with 0 arguments
----------------------------------------------------------------------
Traceback (most recent call last):
  File "/home/ops/ops445/lab3/./CheckLab3.py", line 308, in test_a_function_free_space
    dummy = lab3dStudent.free_space()
  File "/home/ops/ops445/lab3/lab3d.py", line 13, in free_space
    bashclean = bashcommand[0].decode('utf-8').strip()
AttributeError: 'str' object has no attribute 'decode'

During handling of the above exception, another exception occurred:

Traceback (most recent call last):
  File "/home/ops/ops445/lab3/./CheckLab3.py", line 310, in test_a_function_free_space
    self.fail('free_space() function contains errors (HINT: run the function and fix errors')
AssertionError: free_space() function contains errors (HINT: run the function and fix errors

----------------------------------------------------------------------
Ran 31 tests in 0.223s

FAILED (failures=1)
OPS445 Lab Report - System Information for running ./CheckLab3.py
=================================================================
    User login name: ops
    Linux system name: ops-VirtualBox
    Python executable: /usr/bin/python3
    Python version: 3106
    OS Platform: linux
    Working Directory: /home/ops/ops445/lab3
    Start at: Fri May 31 17:14:11 2024
=================================================================
<function free_space at 0x7f5dc95230a0>
